Workbook

Sheet Pipeline
A1: Months | B1: Client/Brand | C1: Brand / Agency | D1: Campagin Name | E1: PIC | F1: Stage/Status | G1: Amount_IDR | H1: Created_Date | I1: Deadline Date | J1: Amount_Deals | K1: PIC Internal | L1: Link Brief | M1: INT Link | N1: EXT Internal | O1: Notes
A2: July 2025 | B2: Ofero | C2: Direct | D2: Ofero x PRJ 2025 & Ride & Fest | E2: Gerry | F2: Finish / Paid | G2: 500000000 | H2: 45839 | I2: 45839 | J2: 508000000
A3: July 2025 | B3: Ofero | C3: Direct | D3: Ofere Design Stareer lit3 | E3: Gerry | F3: Finish / Paid | G3: 250000000 | H3: 45870 | I3: 45874 | J3: 101540816
A4: July 2025 | B4: Injourney | C4: ITDC - Injourney | D4: MotoGP Mandalika 2025 | E4: Gerry | F4: Finish / Paid | G4: 800000000 | H4: 45870 | I4: 45874 | J4: 355810000
A5: July 2025 | B5: XM | C5: Agam | D5: XM Trading | E5: Gerry | F5: Finish / Paid | G5: 50000000 | H5: 45839 | I5: 45839 | J5: 23750000
A6: Aug 2025 | B6: Michelin | C6: Direct | D6: BA for michelin 3 Months | E6: Gerry | F6: Lost | G6: 250000000 | H6: 45870 | I6: 45880
A7: Sept 2025 | B7: Mobil1 | C7: TBWA | D7: Mobil1 Visit Care Car | E7: Gerry | F7: Finish / Paid | G7: 6000000 | H7: 45901 | I7: 45905 | J7: 6000000
A8: Oct 2025 | B8: Mattel | C8: MBCS | D8: Mattel Content Production | E8: Gerry | F8: Lost | G8: 15000000 | H8: 45944 | I8: 45957
A9: Oct 2025 | B9: Fisher Price - Mattel | C9: MBCS | D9: Reco campaign 2026 & Visit Playlab US | E9: Gerry | F9: Lost | G9: 4500000000 | H9: 45944 | I9: 45952
A10: Oct 2025 | B10: Fisher Price - Mattel | C10: MBCS | D10: Affiliate Plan for 2026 | E10: Gerry | F10: Lost | G10: 150000000 | H10: 45944 | I10: 45957
A11: Oct 2025 | B11: Ofero | C11: Direct | D11: Ofero Stareer 3 Lit All Black | E11: Gerry | F11: Finish / Paid | G11: 20000000 | H11: 45958 | I11: 45961
A12: 45962 | B12: Michelin, BFGoodrich, Corsa | C12: Direct | D12: Social Media Retainer | E12: Gerry | F12: Lost | G12: 1000000000 | H12: 45960 | I12: 45974
A13: 45979 | B13: Blue Band | C13: UM IPG | D13: Campaign Q1 - Q3 2026 | E13: Gerry | F13: Lost | G13: 500000000 | H13: 45980 | I13: 45982
A14: 45992 | B14: Ofero | C14: Direct | D14: Ofero Stareer 5 lit Launching | E14: Gerry | F14: Invoicing | G14: 159000000 | J14: 178800000
A15: 46053 | B15: Blue Band | C15: UM IPG | D15: Blueband Dracin | E15: Gerry | F15: Invoicing | G15: 42200000 | J15: 42200000
A16: 46087 | B16: Nyam Nyam | C16: Direct | D16: Nyam Nyam Ramadhan | E16: Gerry | F16: Finish / Paid | G16: 100000000 | J16: 14000000
A17: 46087 | B17: Golden Rama Tours | C17: UM IPG | D17: Surabaya Campaign | E17: Gerry | F17: Lost | G17: 50000000
A18: 46087 | B18: Le Minerale | C18: Direct | D18: KOC Le Minerale - LMGG Umroh | E18: Gerry | F18: Won / On Going | G18: 100000000
A19: 46087 | B19: Ofero | C19: Direct | D19: Ofero Leasing | E19: Gerry | F19: Invoicing | G19: 15000000
A20: May 2026
A21: May 2026 | B21: Arummi | C21: Direct | D21: Social Media Content UGC | E21: Gerry | F21: Won / On Going | G21: 15000000 | J21: 15000000 | K21: Aliy
A22: May 2026 | B22: Gimbory | E22: Gerry | F22: Awaiting Feedback | K22: Aliy
A23: May 2026 | B23: Shopee | C23: Direct | D23: PR Teams - Clippers | E23: Gerry | F23: Awaiting Feedback | G23: 25000000 | K23: Aliy
A24: May 2026 | B24: Golden Rama Tours | C24: UM | D24: SQ Travel Fair | E24: Gerry | F24: Revision | G24: 35000000 | H24: 46161 | I24: 46164 | K24: Aliy | M24: [INT] Golden Rama (SQ Travel Fair) - KOL List | N24: [EXT] Golden Rama (SQ Travel Fair) - KOL List - UM - BV
A25: May 2026 | B25: Cimory | C25: Growmint | D25: Cimory Yoghurt | E25: Gerry | F25: Awaiting Feedback | G25: 500000000 | H25: 46161 | K25: Aliy
A26: May 2026 | B26: GoFood | C26: Curve | D26: Threads Campaign | E26: Wina | F26: Invoicing | G26: 35000000 | H26: 46163 | J26: 1000000 | K26: Aliy | L26: [BVN Brief KOL] GoFood - Threads - Curve - 2026 | M26: [INT] GoFood - Threads - KOL List | N26: [EXT] GoFood - Threads - KOL List
A27: May 2026 | B27: GoPay | C27: Curve | D27: Gamers | E27: Wina | F27: Awaiting Feedback | G27: 50000000 | H27: 46164 | K27: Aliy | L27: [BVN Brief KOL] GoPay - Gamers - Curve - 2026 | M27: [INT] GoPay (Gamers) - KOL List | N27: [EXT] GoPay (Gamers) - KOL List
A28: May 2026 | B28: GoPay | C28: Curve | D28: FIFA Worldcup’26 | E28: Wina | F28: Awaiting Feedback | G28: 100000000 | H28: 46164 | K28: Aliy | L28: [BVN Brief KOL] GoPay - Fifa World Cup'26 - Curve - 2026 | M28: [INT] GoPay (FIFA World Cup '26) - KOL List | N28: [EXT] GoPay (FIFA World Cup '26) - KOL List
A29: May 2026 | B29: Sony Pictures | C29: Direct | D29: Masters of the Universe Int'l Influencer | E29: Wina | F29: Invoicing | G29: 15000000 | H29: 46164 | J29: 15100000 | K29: Aliy | L29: Masters of the Universe Int'l Influencer Timeline [INDONESIA] | M29: INT - Masters of the Universe Movie | N29: [EXT] Masters of the Universe - Sony Pictures - KOL List - BV Network
A30: May 2026 | B30: Manfa Indonesia | C30: Direct | D30: Manfa | E30: Wina | F30: Awaiting Feedback | G30: 50000000 | H30: 46164 | K30: Aliy | L30: [BVN Brief KOL] Manfa May 2026 | M30: [INT] Manfa - KOL List | N30: [EXT] Manfa - KOL List - BVN
A31: May 2026 | B31: Cedea | C31: WebTVAsia | D31: Cedea Seafood | E31: Gerry | F31: Awaiting Feedback | G31: 50000000 | H31: 46168 | K31: Aliy | L31: Copy of Brief Brand Deals CEDEA Seafood - Eomuk Bar Ready To Eat | M31: [INT] Cedea - KOL List
A32: May 2026 | B32: Page By Page | C32: We Thrive | D32: Page By Page Launching | E32: Wina | F32: Revision | G32: 30000000 | H32: 46171 | K32: Aliy | L32: [BVN Brief KOL] Page by Page - 2026 | M32: [INT] Page By Page - KOL List - Wethrive | N32: BV x We Thrive
A33: May 2026 | B33: Vitalis | C33: WebTV Asia | D33: Vitalis ERP 100ml | E33: Gerry | F33: Media Plan | G33: 42500000 | H33: 46171 | K33: Salwa | L33: Brief & Guidelines for Wipro [Vitalis EDP Sparkle 100ML].pdf | M33: [INT] Vitalis - KOL List
A34: June 2026
A35: 46174 | B35: Toys Kingdom | C35: Direct | D35: Toys Kingdom Visit Store | E35: Wina | F35: Awaiting Feedback | G35: Open | H35: 46175 | K35: Aliy | L35: [BVN Brief KOL] Toys Kingdom - 2026 | M35: [INT] Toys Kingdom - KOL List | N35: [EXT] Toys Kingdom - KOL List
A36: 46174 | B36: Planet Ban | C36: Direct | D36: IG Collab | E36: Wina | F36: Won / On Going | G36: 35000000 | H36: 46175 | K36: Salwa | L36: [BVN Brief KOL] Planet Ban - IG Collab - 2026 | M36: [INT] Planet Ban - IG Collab - KOL List | N36: [EXT] Planet Ban - IG Collab - KOL List
A37: 46174 | B37: Planet Ban | C37: Direct | D37: Grand Opening Store @Pekanbaru | E37: Wina | F37: Won / On Going | G37: 100000000 | H37: 46175 | K37: Aliy | L37: [BVN Brief KOL] Planet Ban - Grand Opening Store - 2026 | M37: [INT] Planet Ban - Grand Opening Store @Pekanbaru - KOL List | N37: [EXT] Planet Ban - Grand Opening Store @Pekanbaru - KOL List
A38: 46174 | B38: Planet Ban | C38: Direct | D38: Grand Opening Store @Banjarmasin | E38: Wina | F38: Won / On Going | G38: 50000000 | H38: 46175 | K38: Aliy | L38: [BVN Brief KOL] Planet Ban - Grand Opening Store - 2026 | M38: [INT] Planet Ban - Grand Opening Store @Banjarmasin - KOL List | N38: [EXT] Planet Ban - Grand Opening Store @Banjarmasin - KOL List
A39: 46174 | B39: Planet Ban | C39: Direct | D39: Youtube Podcast X ABG Siniar | E39: Wina | F39: Media Plan | K39: Salwa | M39: [INT] Planet Ban - Youtube Podcast ABG Siniar - KOL List | N39: [EXT] Planet Ban - Youtube Podcast ABG Siniar - KOL List
A40: 46174 | B40: Planet Ban | C40: Direct | D40: Talent Shoot | E40: Wina | F40: Won / On Going | G40: 4000000 | H40: 46175 | K40: Gress | L40: [BVN Brief KOL] Planet Ban - Talent Shoot - 2026 | M40: [INT] Talent Shoot - Planet Ban - List | N40: [EXT] Talent Shoot - Planet Ban - List
...

Sheet Campaigns
A1: Campaign_Name | B1: Client | C1: Brand/Agency | D1: PIC | E1: Start_Date | F1: End_Date | G1: Budget Deals_IDR | H1: Real Cost_IDR | I1: INTERNAL Link | J1: EXT Link | K1: PIC Clients | L1: Entity Names | M1: Link Folder | N1: Margin | O1: Gross Profit_IDR | P1: Status Campaign | Q1: Invoice Date | R1: Remarks
A2: Ofero PRJ x Ride & Fest | B2: Ofero | C2: Direct | D2: Gerry | E2: 45829 | F2: 45935 | G2: 508000000 | H2: 242075374 | K2: Nabillah | L2: PT Ofero Technology Indonesia | M2: Ofero PRJ x Ride & Fest | N2: =O2/G2 -> 0.52347367 | O2: =G2-H2 -> 265924626 | P2: Finish/Paid
A3: XM Trading Instagram | B3: XM | C3: Agam | D3: Gerry | E3: 45870 | F3: 45930 | G3: 23750000 | H3: 10000000 | K3: Agam | L3: Freelance | M3: XM - Trading July | N3: =O3/G3 -> 0.57894737 | O3: =G3-H3 -> 13750000 | P3: Finish/Paid
A4: Ofero Design EBike - Starer 3 lit | B4: Ofero | C4: Direct | D4: Gerry | E4: 45877 | F4: 45907 | G4: 101540816 | H4: 36217686 | K4: Nabillah | L4: PT Ofero Technology Indonesia | M4: Ofero - Design Starrer 3 lit | N4: =O4/G4 -> 0.64331894 | O4: =G4-H4 -> 65323130 | P4: Finish/Paid
A5: MotoGP 2025 - Injourney | B5: ITDC - Injouney | C5: Direct | D5: Gerry | E5: 45901 | F5: 45940 | G5: 355810000 | H5: 177313096 | K5: Maya | L5: PT MGPA NUSANTARA JAYA | M5: ITDC - InJourney MotoGp 2025 | N5: =O5/G5 -> 0.50166354 | O5: =G5-H5 -> 178496904 | P5: Finish/Paid
A6: Mobil1 Visit Care Car - Gussbagus | B6: Mobil1 | C6: TBWA | D6: Gerry | E6: 45931 | F6: 45961 | G6: 6000000 | H6: 2500000 | K6: Devanka | L6: PT Cipta Kreasi Pariwara | M6: Mobil1 - Visit Care Car Gussbagus - TBWA | N6: =O6/G6 -> 0.58333333 | O6: =G6-H6 -> 3500000 | P6: Finish/Paid
A7: 2026 | N7: =O7/G7 -> #DIV/0! | O7: =G7-H7 -> 0
A8: Ofero Launching Stareer 5 lit | B8: Ofero | C8: Direct | D8: Gerry | G8: 159000000 | H8: 85000000 | K8: Nabillah | L8: PT Ofero Technology Indonesia | M8: Ofero Stareer 5 Lit - Ofero - Apr'26 | N8: =O8/G8 -> 0.4654088 | O8: =G8-H8 -> 74000000 | P8: Report
A9: Blueband Dracin | B9: Blue Band | C9: UM IPG | D9: Gerry | G9: 42200000 | H9: 19800000 | K9: Eca | L9: PT Inter Pariwara Global | M9: Blue Band - Dracin Campagin - UM IPG - Jan'26 | N9: =O9/G9 -> 0.53080569 | O9: =G9-H9 -> 22400000 | P9: Waiting Payment
A10: Nyam Nyam | B10: Arnott's | C10: Direct | D10: Gerry | G10: 14000000 | H10: 10853200 | I10: =Pipeline!M16 | J10: =Pipeline!N16 | K10: Feny Listianti | L10: PT Anrott's Indonesia | M10: Nyam Nyam - Ramadan Campaign Nyambutmudik - Apr'26 | N10: =O10/G10 -> 0.22477143 | O10: =G10-H10 -> 3146800 | P10: Waiting Payment
A11: Le Minerale - LMGG | B11: Le Minerale | C11: Direct | D11: Gerry | G11: 100000000 | N11: =O11/G11 -> 1 | O11: =G11-H11 -> 100000000 | P11: On Going
A12: Ofero Leasing | B12: Ofero | C12: Direct | D12: Gerry | G12: 15000000 | N12: =O12/G12 -> 1 | O12: =G12-H12 -> 15000000 | P12: Report
A13: Arummi | B13: Arummi | C13: Direct | D13: Gerry | G13: 15000000 | N13: =O13/G13 -> 1 | O13: =G13-H13 -> 15000000 | P13: On Going
A14: Masters of the Universe Int'l Influencer | B14: Sony Pictures | C14: Direct | D14: Wina | G14: 15000000 | H14: 6533333 | K14: Sasha | L14: PT Omega | N14: =O14/G14 -> 0.56444447 | O14: =G14-H14 -> 8466667 | P14: Report
A15: Minions & Monster - UIP | B15: UIP | C15: Direct | D15: Wina | G15: 104400000 | O15: =G15-H15 -> 104400000
A16: Planet Ban - Banjarmasin | B16: Planet Ban | C16: Direct | D16: Wina | G16: 78329000 | O16: =G16-H16 -> 78329000
A17: Planet Ban - Pekanbaru | B17: Planet Ban | C17: Direct | D17: Wina | G17: 57398000 | O17: =G17-H17 -> 57398000
A18: Planet Ban - IG Collab | B18: Planet Ban | C18: Direct | D18: Wina | G18: 15295000 | O18: =G18-H18 -> 15295000
A19: Planet Ban - Talent | B19: Planet Ban | C19: Direct | D19: Wina | G19: 4000000 | O19: =G19-H19 -> 4000000
A20: Planet Ban - YT Podcast | B20: Planet Ban | C20: Direct | D20: Wina | G20: 20000000 | O20: =G20-H20 -> 20000000
G21: =SUM(G11:G20) -> 424422000 | O21: =G21-H21 -> 424422000
O22: =G22-H22 -> 0
O23: =G23-H23 -> 0
O24: =G24-H24 -> 0
O25: =G25-H25 -> 0
O26: =G26-H26 -> 0

Sheet Inputs_Targets
A1: Month (YYYY-MM) | B1: Company_Target_IDR | C1: Salesperson | D1: Salesperson_Target_IDR
A2: 2025-10 | B2: 1500000000 | C2: GERRY | D2: 500000000
A3: 2025-10 | D3: 1000000000
A4: 2025-11 | B4: 1500000000 | C4: GERRY | D4: 500000000
A5: 2025-11 | D5: 1000000000
A6: 2025-12 | B6: 1500000000 | C6: GERRY | D6: 500000000
A7: 2025-12 | D7: 1000000000
A8: 2026-01 | B8: 1500000000 | C8: GERRY | D8: 500000000
A9: 2026-01 | D9: 1000000000
A10: 2026-02 | B10: 1500000000 | C10: GERRY | D10: 500000000
A11: 2026-02 | D11: 1000000000
A12: 2026-03 | B12: 1500000000 | C12: GERRY | D12: 500000000
A13: 2026-03 | D13: 1000000000
A14: 2026-04 | B14: 1500000000 | C14: GERRY | D14: 500000000
A15: 2026-04 | D15: 1000000000
A16: 2026-05 | B16: 1500000000 | C16: GERRY | D16: 500000000
A17: 2026-05 | D17: 1000000000
A18: 2026-06 | B18: 1500000000 | C18: GERRY | D18: 500000000
A19: 2026-06 | D19: 1000000000
A20: 2026-07 | B20: 1500000000 | C20: GERRY | D20: 500000000
A21: 2026-07 | D21: 1000000000

Sheet Dashboard
A1: Hybrid Sales & Campaign Dashboard (IDR)
A3: Selected Month | B3: 2025-10 | D3: Per Salesperson – Selected Month
D4: Salesperson | E4: Target_IDR | F4: Won_IDR | G4: Variance_IDR | H4: Monthly Trend (Targets vs Actual Won)
A5: Company Target (IDR) | B5: =IFERROR(SUMIFS(Inputs_Targets!B:B, Inputs_Targets!A:A, $B$3),0) -> 1500000000 | D5: =IFERROR(Helper!A2,"") -> GERRY | E5: =IF($D5="",,SUMIFS(Inputs_Targets!D:D,Inputs_Targets!A:A,$B$3,Inputs_Targets!C:C,$D5)) -> 500000000 | F5: =IF($D5="",,SUMPRODUCT((Pipeline!E:E=$D5)*(Pipeline!F:F="Won")*(TEXT(Pipeline!I:I,"yyyy-mm")=$B$3)*Pipeline!G:G)) -> #VALUE! | G5: =IF($D5="",,E5-F5) -> #VALUE! | H5: Month | I5: Company_Target_IDR | J5: Actual_Won_IDR
A6: Actual Sales (Won) (IDR) | B6: =IFERROR(__xludf.DUMMYFUNCTION("IFERROR(SUM(FILTER(Pipeline!G:G, Pipeline!F:F=""Won"", TEXT(Pipeline!I:I,""yyyy-mm"")=$B$3 )),0) "),0.0) -> 0 | D6: =IFERROR(Helper!A3,"") -> Salesperson | E6: =IF($D6="",,SUMIFS(Inputs_Targets!D:D,Inputs_Targets!A:A,$B$3,Inputs_Targets!C:C,$D6)) -> 0 | F6: =IF($D6="",,SUMPRODUCT((Pipeline!E:E=$D6)*(Pipeline!F:F="Won")*(TEXT(Pipeline!I:I,"yyyy-mm")=$B$3)*Pipeline!G:G)) -> #VALUE! | G6: =IF($D6="",,E6-F6) -> #VALUE! | H6: 2025-10 | I6: =SUMIFS(Inputs_Targets!B:B,Inputs_Targets!A:A,I6) -> #REF! | J6: =SUMPRODUCT((Pipeline!F:F="Won")*(TEXT(Pipeline!I:I,"yyyy-mm")=I6)*Pipeline!G:G) -> #REF!
A7: % Achieved | B7: =IFERROR(B6/B5,0) -> 0 | D7: =IFERROR(Helper!A4,"") | E7: =IF($D7="",,SUMIFS(Inputs_Targets!D:D,Inputs_Targets!A:A,$B$3,Inputs_Targets!C:C,$D7)) | F7: =IF($D7="",,SUMPRODUCT((Pipeline!E:E=$D7)*(Pipeline!F:F="Won")*(TEXT(Pipeline!I:I,"yyyy-mm")=$B$3)*Pipeline!G:G)) | G7: =IF($D7="",,E7-F7) | H7: 2025-11 | I7: =SUMIFS(Inputs_Targets!B:B,Inputs_Targets!A:A,I7) -> #REF! | J7: =SUMPRODUCT((Pipeline!F:F="Won")*(TEXT(Pipeline!I:I,"yyyy-mm")=I7)*Pipeline!G:G) -> #REF!
A8: Variance (IDR) | B8: =B6-B5 -> -1500000000 | D8: =IFERROR(Helper!A5,"") | E8: =IF($D8="",,SUMIFS(Inputs_Targets!D:D,Inputs_Targets!A:A,$B$3,Inputs_Targets!C:C,$D8)) | F8: =IF($D8="",,SUMPRODUCT((Pipeline!E:E=$D8)*(Pipeline!F:F="Won")*(TEXT(Pipeline!I:I,"yyyy-mm")=$B$3)*Pipeline!G:G)) | G8: =IF($D8="",,E8-F8) | H8: 2025-12 | I8: =SUMIFS(Inputs_Targets!B:B,Inputs_Targets!A:A,I8) -> #REF! | J8: =SUMPRODUCT((Pipeline!F:F="Won")*(TEXT(Pipeline!I:I,"yyyy-mm")=I8)*Pipeline!G:G) -> #REF!
A9: Open Pipeline Amount (IDR) | B9: =IFERROR(__xludf.DUMMYFUNCTION("IFERROR(SUM(FILTER(Pipeline!G:G, Pipeline!F:F<>""Won"", Pipeline!F:F<>""Lost"" )),0) "),3.1787E9) -> 3178700000 | D9: =IFERROR(Helper!A6,"") | E9: =IF($D9="",,SUMIFS(Inputs_Targets!D:D,Inputs_Targets!A:A,$B$3,Inputs_Targets!C:C,$D9)) | F9: =IF($D9="",,SUMPRODUCT((Pipeline!E:E=$D9)*(Pipeline!F:F="Won")*(TEXT(Pipeline!I:I,"yyyy-mm")=$B$3)*Pipeline!G:G)) | G9: =IF($D9="",,E9-F9) | H9: 2026-01 | I9: =SUMIFS(Inputs_Targets!B:B,Inputs_Targets!A:A,I9) -> #REF! | J9: =SUMPRODUCT((Pipeline!F:F="Won")*(TEXT(Pipeline!I:I,"yyyy-mm")=I9)*Pipeline!G:G) -> #REF!
A10: Open Deals Count | B10: =IFERROR(__xludf.DUMMYFUNCTION("IFERROR(COUNTA(FILTER(Pipeline!A:A, Pipeline!F:F<>""Won"", Pipeline!F:F<>""Lost"" )),0) "),42.0) -> 42 | D10: =IFERROR(Helper!A7,"") | E10: =IF($D10="",,SUMIFS(Inputs_Targets!D:D,Inputs_Targets!A:A,$B$3,Inputs_Targets!C:C,$D10)) | F10: =IF($D10="",,SUMPRODUCT((Pipeline!E:E=$D10)*(Pipeline!F:F="Won")*(TEXT(Pipeline!I:I,"yyyy-mm")=$B$3)*Pipeline!G:G)) | G10: =IF($D10="",,E10-F10) | H10: 2026-02 | I10: =SUMIFS(Inputs_Targets!B:B,Inputs_Targets!A:A,I10) -> #REF! | J10: =SUMPRODUCT((Pipeline!F:F="Won")*(TEXT(Pipeline!I:I,"yyyy-mm")=I10)*Pipeline!G:G) -> #REF!
A11: Win Rate (Last 90 Days) | B11: =IFERROR(SUMPRODUCT((Pipeline!F:F="Won")*(Pipeline!I:I>=TODAY()-90)) / SUMPRODUCT(((Pipeline!F:F="Won")+(Pipeline!F:F="Lost"))*(Pipeline!I:I>=TODAY()-90)),0) -> 0 | D11: =IFERROR(Helper!A8,"") | E11: =IF($D11="",,SUMIFS(Inputs_Targets!D:D,Inputs_Targets!A:A,$B$3,Inputs_Targets!C:C,$D11)) | F11: =IF($D11="",,SUMPRODUCT((Pipeline!E:E=$D11)*(Pipeline!F:F="Won")*(TEXT(Pipeline!I:I,"yyyy-mm")=$B$3)*Pipeline!G:G)) | G11: =IF($D11="",,E11-F11) | H11: 2026-03 | I11: =SUMIFS(Inputs_Targets!B:B,Inputs_Targets!A:A,I11) -> #REF! | J11: =SUMPRODUCT((Pipeline!F:F="Won")*(TEXT(Pipeline!I:I,"yyyy-mm")=I11)*Pipeline!G:G) -> #REF!
A12: Avg Sales Cycle (Days, Won) | B12: =IFERROR(AVERAGE(IF((Pipeline!F:F="Won")*(Pipeline!I:I<>"" )*(Pipeline!H:H<>""), Pipeline!I:I - Pipeline!H:H)), 0) -> 0 | D12: =IFERROR(Helper!A9,"") | E12: =IF($D12="",,SUMIFS(Inputs_Targets!D:D,Inputs_Targets!A:A,$B$3,Inputs_Targets!C:C,$D12)) | F12: =IF($D12="",,SUMPRODUCT((Pipeline!E:E=$D12)*(Pipeline!F:F="Won")*(TEXT(Pipeline!I:I,"yyyy-mm")=$B$3)*Pipeline!G:G)) | G12: =IF($D12="",,E12-F12) | H12: =IF($D12="",,IFERROR(F12/E12,0))
D13: =IFERROR(Helper!A10,"") | E13: =IF($D13="",,SUMIFS(Inputs_Targets!D:D,Inputs_Targets!A:A,$B$3,Inputs_Targets!C:C,$D13)) | F13: =IF($D13="",,SUMPRODUCT((Pipeline!E:E=$D13)*(Pipeline!F:F="Won")*(TEXT(Pipeline!I:I,"yyyy-mm")=$B$3)*Pipeline!G:G)) | G13: =IF($D13="",,E13-F13) | H13: =IF($D13="",,IFERROR(F13/E13,0))
D14: =IFERROR(Helper!A11,"") | E14: =IF($D14="",,SUMIFS(Inputs_Targets!D:D,Inputs_Targets!A:A,$B$3,Inputs_Targets!C:C,$D14)) | F14: =IF($D14="",,SUMPRODUCT((Pipeline!E:E=$D14)*(Pipeline!F:F="Won")*(TEXT(Pipeline!I:I,"yyyy-mm")=$B$3)*Pipeline!G:G)) | G14: =IF($D14="",,E14-F14) | H14: =IF($D14="",,IFERROR(F14/E14,0))
D15: =IFERROR(Helper!A12,"") | E15: =IF($D15="",,SUMIFS(Inputs_Targets!D:D,Inputs_Targets!A:A,$B$3,Inputs_Targets!C:C,$D15)) | F15: =IF($D15="",,SUMPRODUCT((Pipeline!E:E=$D15)*(Pipeline!F:F="Won")*(TEXT(Pipeline!I:I,"yyyy-mm")=$B$3)*Pipeline!G:G)) | G15: =IF($D15="",,E15-F15) | H15: =IF($D15="",,IFERROR(F15/E15,0))
D16: =IFERROR(Helper!A13,"") | E16: =IF($D16="",,SUMIFS(Inputs_Targets!D:D,Inputs_Targets!A:A,$B$3,Inputs_Targets!C:C,$D16)) | F16: =IF($D16="",,SUMPRODUCT((Pipeline!E:E=$D16)*(Pipeline!F:F="Won")*(TEXT(Pipeline!I:I,"yyyy-mm")=$B$3)*Pipeline!G:G)) | G16: =IF($D16="",,E16-F16) | H16: =IF($D16="",,IFERROR(F16/E16,0))
D17: =IFERROR(Helper!A14,"") | E17: =IF($D17="",,SUMIFS(Inputs_Targets!D:D,Inputs_Targets!A:A,$B$3,Inputs_Targets!C:C,$D17)) | F17: =IF($D17="",,SUMPRODUCT((Pipeline!E:E=$D17)*(Pipeline!F:F="Won")*(TEXT(Pipeline!I:I,"yyyy-mm")=$B$3)*Pipeline!G:G)) | G17: =IF($D17="",,E17-F17) | H17: =IF($D17="",,IFERROR(F17/E17,0))
D18: =IFERROR(Helper!A15,"") | E18: =IF($D18="",,SUMIFS(Inputs_Targets!D:D,Inputs_Targets!A:A,$B$3,Inputs_Targets!C:C,$D18)) | F18: =IF($D18="",,SUMPRODUCT((Pipeline!E:E=$D18)*(Pipeline!F:F="Won")*(TEXT(Pipeline!I:I,"yyyy-mm")=$B$3)*Pipeline!G:G)) | G18: =IF($D18="",,E18-F18) | H18: =IF($D18="",,IFERROR(F18/E18,0))
D19: =IFERROR(Helper!A16,"") | E19: =IF($D19="",,SUMIFS(Inputs_Targets!D:D,Inputs_Targets!A:A,$B$3,Inputs_Targets!C:C,$D19)) | F19: =IF($D19="",,SUMPRODUCT((Pipeline!E:E=$D19)*(Pipeline!F:F="Won")*(TEXT(Pipeline!I:I,"yyyy-mm")=$B$3)*Pipeline!G:G)) | G19: =IF($D19="",,E19-F19) | H19: =IF($D19="",,IFERROR(F19/E19,0))
D20: =IFERROR(Helper!A17,"") | E20: =IF($D20="",,SUMIFS(Inputs_Targets!D:D,Inputs_Targets!A:A,$B$3,Inputs_Targets!C:C,$D20)) | F20: =IF($D20="",,SUMPRODUCT((Pipeline!E:E=$D20)*(Pipeline!F:F="Won")*(TEXT(Pipeline!I:I,"yyyy-mm")=$B$3)*Pipeline!G:G)) | G20: =IF($D20="",,E20-F20) | H20: =IF($D20="",,IFERROR(F20/E20,0))
D21: =IFERROR(Helper!A18,"") | E21: =IF($D21="",,SUMIFS(Inputs_Targets!D:D,Inputs_Targets!A:A,$B$3,Inputs_Targets!C:C,$D21)) | F21: =IF($D21="",,SUMPRODUCT((Pipeline!E:E=$D21)*(Pipeline!F:F="Won")*(TEXT(Pipeline!I:I,"yyyy-mm")=$B$3)*Pipeline!G:G)) | G21: =IF($D21="",,E21-F21) | H21: =IF($D21="",,IFERROR(F21/E21,0))
D22: =IFERROR(Helper!A19,"") | E22: =IF($D22="",,SUMIFS(Inputs_Targets!D:D,Inputs_Targets!A:A,$B$3,Inputs_Targets!C:C,$D22)) | F22: =IF($D22="",,SUMPRODUCT((Pipeline!E:E=$D22)*(Pipeline!F:F="Won")*(TEXT(Pipeline!I:I,"yyyy-mm")=$B$3)*Pipeline!G:G)) | G22: =IF($D22="",,E22-F22) | H22: =IF($D22="",,IFERROR(F22/E22,0))
D23: =IFERROR(Helper!A20,"") | E23: =IF($D23="",,SUMIFS(Inputs_Targets!D:D,Inputs_Targets!A:A,$B$3,Inputs_Targets!C:C,$D23)) | F23: =IF($D23="",,SUMPRODUCT((Pipeline!E:E=$D23)*(Pipeline!F:F="Won")*(TEXT(Pipeline!I:I,"yyyy-mm")=$B$3)*Pipeline!G:G)) | G23: =IF($D23="",,E23-F23) | H23: =IF($D23="",,IFERROR(F23/E23,0))
D24: =IFERROR(Helper!A21,"") | E24: =IF($D24="",,SUMIFS(Inputs_Targets!D:D,Inputs_Targets!A:A,$B$3,Inputs_Targets!C:C,$D24)) | F24: =IF($D24="",,SUMPRODUCT((Pipeline!E:E=$D24)*(Pipeline!F:F="Won")*(TEXT(Pipeline!I:I,"yyyy-mm")=$B$3)*Pipeline!G:G)) | G24: =IF($D24="",,E24-F24) | H24: =IF($D24="",,IFERROR(F24/E24,0))

Sheet Helper
A1: Unique_Salespeople
A2: =IFERROR(__xludf.DUMMYFUNCTION("SORT(UNIQUE(FILTER(Inputs_Targets!C:C,Inputs_Targets!C:C<>"""")))"),"GERRY") -> GERRY
A3: =IFERROR(__xludf.DUMMYFUNCTION("""COMPUTED_VALUE"""),"Salesperson") -> Salesperson
